모델: kullm-v2
오류 타입: ValueError
오류 메시지: Target modules ['q_proj', 'k_proj', 'v_proj', 'o_proj', 'gate_proj', 'up_proj', 'down_proj'] not found in the base model. Please check the target modules and try again.

상세 트레이스백:
Traceback (most recent call last):
  File "/home/ieyeppo/AI_Lab/natural-language-processing-competition/src/trainers/full_pipeline_trainer.py", line 183, in _train_multiple_models
    model, tokenizer = load_model_and_tokenizer(config, logger=self.logger)
                       ^^^^^^^^^^^^^^^^^^^^^^^^^^^^^^^^^^^^^^^^^^^^^^^^^^^^
  File "/home/ieyeppo/AI_Lab/natural-language-processing-competition/src/models/__init__.py", line 43, in load_model_and_tokenizer
    return load_causal_lm(config, logger)
           ^^^^^^^^^^^^^^^^^^^^^^^^^^^^^^
  File "/home/ieyeppo/AI_Lab/natural-language-processing-competition/src/models/llm_loader.py", line 124, in load_causal_lm
    model = get_peft_model(model, lora_config)
            ^^^^^^^^^^^^^^^^^^^^^^^^^^^^^^^^^^
  File "/home/ieyeppo/.pyenv/versions/nlp_py3_11_9/lib/python3.11/site-packages/peft/mapping_func.py", line 125, in get_peft_model
    return MODEL_TYPE_TO_PEFT_MODEL_MAPPING[peft_config.task_type](
           ^^^^^^^^^^^^^^^^^^^^^^^^^^^^^^^^^^^^^^^^^^^^^^^^^^^^^^^^
  File "/home/ieyeppo/.pyenv/versions/nlp_py3_11_9/lib/python3.11/site-packages/peft/peft_model.py", line 1815, in __init__
    super().__init__(model, peft_config, adapter_name, **kwargs)
  File "/home/ieyeppo/.pyenv/versions/nlp_py3_11_9/lib/python3.11/site-packages/peft/peft_model.py", line 130, in __init__
    self.base_model = cls(model, {adapter_name: peft_config}, adapter_name)
                      ^^^^^^^^^^^^^^^^^^^^^^^^^^^^^^^^^^^^^^^^^^^^^^^^^^^^^
  File "/home/ieyeppo/.pyenv/versions/nlp_py3_11_9/lib/python3.11/site-packages/peft/tuners/tuners_utils.py", line 209, in __init__
    self.inject_adapter(self.model, adapter_name, low_cpu_mem_usage=low_cpu_mem_usage, state_dict=state_dict)
  File "/home/ieyeppo/.pyenv/versions/nlp_py3_11_9/lib/python3.11/site-packages/peft/tuners/tuners_utils.py", line 654, in inject_adapter
    raise ValueError(error_msg)
ValueError: Target modules ['q_proj', 'k_proj', 'v_proj', 'o_proj', 'gate_proj', 'up_proj', 'down_proj'] not found in the base model. Please check the target modules and try again.
