모델: llama-3.2-korean-3b
오류 타입: AttributeError
오류 메시지: 'Logger' object has no attribute 'isatty'

상세 트레이스백:
Traceback (most recent call last):
  File "/home/ieyeppo/AI_Lab/natural-language-processing-competition/src/trainers/full_pipeline_trainer.py", line 225, in _train_multiple_models
    train_result = trainer.train()
                   ^^^^^^^^^^^^^^^
  File "/home/ieyeppo/AI_Lab/natural-language-processing-competition/src/training/trainer.py", line 251, in train
    self.wandb_logger.init_run()                # WandB Run 초기화
    ^^^^^^^^^^^^^^^^^^^^^^^^^^^^
  File "/home/ieyeppo/AI_Lab/natural-language-processing-competition/src/logging/wandb_logger.py", line 78, in init_run
    self.run = wandb.init(
               ^^^^^^^^^^^
  File "/home/ieyeppo/.pyenv/versions/nlp_py3_11_9/lib/python3.11/site-packages/wandb/sdk/wandb_init.py", line 1601, in init
    wandb._sentry.reraise(e)
  File "/home/ieyeppo/.pyenv/versions/nlp_py3_11_9/lib/python3.11/site-packages/wandb/analytics/sentry.py", line 162, in reraise
    raise exc.with_traceback(sys.exc_info()[2])
  File "/home/ieyeppo/.pyenv/versions/nlp_py3_11_9/lib/python3.11/site-packages/wandb/sdk/wandb_init.py", line 1582, in init
    run = wi.init(run_settings, run_config, run_printer)
          ^^^^^^^^^^^^^^^^^^^^^^^^^^^^^^^^^^^^^^^^^^^^^^
  File "/home/ieyeppo/.pyenv/versions/nlp_py3_11_9/lib/python3.11/site-packages/wandb/sdk/wandb_init.py", line 1004, in init
    result = wait_with_progress(
             ^^^^^^^^^^^^^^^^^^^
  File "/home/ieyeppo/.pyenv/versions/nlp_py3_11_9/lib/python3.11/site-packages/wandb/sdk/mailbox/wait_with_progress.py", line 23, in wait_with_progress
    return wait_all_with_progress(
           ^^^^^^^^^^^^^^^^^^^^^^^
  File "/home/ieyeppo/.pyenv/versions/nlp_py3_11_9/lib/python3.11/site-packages/wandb/sdk/mailbox/wait_with_progress.py", line 77, in wait_all_with_progress
    return asyncer.run(progress_loop_with_timeout)
           ^^^^^^^^^^^^^^^^^^^^^^^^^^^^^^^^^^^^^^^
  File "/home/ieyeppo/.pyenv/versions/nlp_py3_11_9/lib/python3.11/site-packages/wandb/sdk/lib/asyncio_manager.py", line 136, in run
    return future.result()
           ^^^^^^^^^^^^^^^
  File "/home/ieyeppo/.pyenv/versions/3.11.9/lib/python3.11/concurrent/futures/_base.py", line 456, in result
    return self.__get_result()
           ^^^^^^^^^^^^^^^^^^^
  File "/home/ieyeppo/.pyenv/versions/3.11.9/lib/python3.11/concurrent/futures/_base.py", line 401, in __get_result
    raise self._exception
  File "/home/ieyeppo/.pyenv/versions/nlp_py3_11_9/lib/python3.11/site-packages/wandb/sdk/lib/asyncio_manager.py", line 219, in _wrap
    return await fn()
           ^^^^^^^^^^
  File "/home/ieyeppo/.pyenv/versions/nlp_py3_11_9/lib/python3.11/site-packages/wandb/sdk/mailbox/wait_with_progress.py", line 65, in progress_loop_with_timeout
    async with asyncio_compat.cancel_on_exit(display_progress()):
  File "/home/ieyeppo/.pyenv/versions/3.11.9/lib/python3.11/contextlib.py", line 217, in __aexit__
    await anext(self.gen)
  File "/home/ieyeppo/.pyenv/versions/nlp_py3_11_9/lib/python3.11/site-packages/wandb/sdk/lib/asyncio_compat.py", line 257, in cancel_on_exit
    async with open_task_group(race=True) as group:
  File "/home/ieyeppo/.pyenv/versions/3.11.9/lib/python3.11/contextlib.py", line 217, in __aexit__
    await anext(self.gen)
  File "/home/ieyeppo/.pyenv/versions/nlp_py3_11_9/lib/python3.11/site-packages/wandb/sdk/lib/asyncio_compat.py", line 240, in open_task_group
    await task_group._wait_all(race=race, timeout=exit_timeout)
  File "/home/ieyeppo/.pyenv/versions/nlp_py3_11_9/lib/python3.11/site-packages/wandb/sdk/lib/asyncio_compat.py", line 180, in _wait_all
    raise exc
  File "/home/ieyeppo/.pyenv/versions/nlp_py3_11_9/lib/python3.11/site-packages/wandb/sdk/wandb_init.py", line 994, in display_init_message
    with progress.progress_printer(
  File "/home/ieyeppo/.pyenv/versions/3.11.9/lib/python3.11/contextlib.py", line 137, in __enter__
    return next(self.gen)
           ^^^^^^^^^^^^^^
  File "/home/ieyeppo/.pyenv/versions/nlp_py3_11_9/lib/python3.11/site-packages/wandb/sdk/lib/progress.py", line 76, in progress_printer
    with printer.dynamic_text() as text_area:
  File "/home/ieyeppo/.pyenv/versions/3.11.9/lib/python3.11/contextlib.py", line 137, in __enter__
    return next(self.gen)
           ^^^^^^^^^^^^^^
  File "/home/ieyeppo/.pyenv/versions/nlp_py3_11_9/lib/python3.11/site-packages/wandb/sdk/lib/printer.py", line 297, in dynamic_text
    with term.dynamic_text() as handle:
  File "/home/ieyeppo/.pyenv/versions/3.11.9/lib/python3.11/contextlib.py", line 137, in __enter__
    return next(self.gen)
           ^^^^^^^^^^^^^^
  File "/home/ieyeppo/.pyenv/versions/nlp_py3_11_9/lib/python3.11/site-packages/wandb/errors/term.py", line 114, in dynamic_text
    if not _sys_stderr_isatty():
           ^^^^^^^^^^^^^^^^^^^^
  File "/home/ieyeppo/.pyenv/versions/nlp_py3_11_9/lib/python3.11/site-packages/wandb/errors/term.py", line 150, in _sys_stderr_isatty
    return sys.stderr.isatty()
           ^^^^^^^^^^^^^^^^^
AttributeError: 'Logger' object has no attribute 'isatty'
